Workbook

Sheet Summary
A1: ENReT v1.0.0 — Numerical validation
A2: All results are computed by formulas from the other sheets. Criterion for certified or independently computed references: LRE ≥ 5 (at least 5 correct significant digits).
A4: Validation | B4: Reference | C4: Comparisons | D4: Minimum LRE | E4: LRE ≥ 5 | F4: Share LRE ≥ 5 | G4: Notes
A5: NIST: parameters and RSS | B5: Certified values (NIST) | C5: =COUNT(NIST!G6:G291) -> 286 | D5: =MIN(NIST!G6:G291) -> 0.079893145 | E5: =COUNTIF(NIST!G6:G291,">=5") -> 282 | F5: =E5/C5 -> 0.98601399 | G5: Roszman1: typo in the certified values (known); otherwise all ≥ 5.
A6: NIST: standard errors | B6: Certified values (NIST) | C6: =COUNT(NIST!J6:J291) -> 234 | D6: =MIN(NIST!J6:J291) -> 2.9842305 | E6: =COUNTIF(NIST!J6:J291,">=5") -> 222 | F6: =E6/C6 -> 0.94871795 | G6: Lanczos1: certified RSS near the rounding limit (known).
A7: Bates & Watts: parameters and RSS | B7: Exact minimum computed in R | C7: =COUNT(Bates_Watts!E6:E62) -> 57 | D7: =MIN(Bates_Watts!E6:E62) -> 6.2752013 | E7: =COUNTIF(Bates_Watts!E6:E62,">=5") -> 57 | F7: =E7/C7 -> 1 | G7: Independent computation, not certified values.
A8: Bates & Watts: standard errors | B8: Exact minimum computed in R | C8: =COUNT(Bates_Watts!H6:H62) -> 42 | D8: =MIN(Bates_Watts!H6:H62) -> 5.3933349 | E8: =COUNTIF(Bates_Watts!H6:H62,">=5") -> 42 | F8: =E8/C8 -> 1
A9: Esterase: weighted and unweighted | B9: R lm() | C9: =COUNT(Esterase!E6:E15) -> 10 | D9: =MIN(Esterase!E6:E15) -> 9.377352 | E9: =COUNTIF(Esterase!E6:E15,">=5") -> 10 | F9: =E9/C9 -> 1 | G9: Small differences from the published book values: see sheet Esterase.
A11: ComBase (agreement with a reference software)
A12: Parameters compared | C12: =COUNT(ComBase!J6:J159) -> 102
A13: Median |z| (difference in ComBase SE) | C13: =MEDIAN(ComBase!J6:J159) -> 0.21837911
A14: Share with |z| < 0.5 | C14: =COUNTIF(ComBase!J6:J159,"<0.5")/COUNT(ComBase!J6:J159) -> 0.73529412
A15: Share with |z| < 1 | C15: =COUNTIF(ComBase!J6:J159,"<1")/COUNT(ComBase!J6:J159) -> 0.89215686
A16: Maximum |z| | C16: =MAX(ComBase!J6:J159) -> 2.0911909
A18: Same model as ComBase (verified: the app's Integrated Baranyi Model on ln counts and the log10 custom formula agree to 7–8 digits). Lag and μmax of the app are a few % lower; the app's residual error is equal to or lower than ComBase's SE of Fit in 20 of 26 curves.
A19: Detailed checks on B419_12 (sheet ComBase_B419_12): the linear model, with a closed-form solution, agrees with ComBase in every digit (same data, standard errors and SE of Fit); with the Baranyi model the app's minimum has less than half the ComBase sum of squares and is better on every criterion. ComBase “R-square” is the adjusted R².

Sheet NIST
A1: NIST StRD — 26 nonlinear regression datasets
A2: Certified values: NIST Statistical Reference Datasets (files .dat). App: ENReT v1.0.0, model from “Models for Reference Data”, Levenberg-Marquardt, Max Iterations 1024.
A3: LRE = −log10(|App − Certified| / |Certified|), capped at 15 (identical values). Blue: input values; black: formulas. Known issues: Roszman1 (typo in the certified values), Lanczos1 (certified RSS near the rounding limit).
A5: Dataset | B5: Difficulty | C5: Start | D5: Quantity | E5: Certified | F5: App | G5: LRE | H5: SE certified | I5: SE app | J5: LRE SE
A6: Bennett5 | B6: Higher Level of Difficulty | C6: 1 | D6: b1 | E6: -2523.5058 | F6: -2523.5058 | G6: =IF(F6="","",IF(F6=E6,15,MIN(15,-LOG10(ABS(F6-E6)/ABS(E6))))) -> 12.018159 | H6: 297.15175 | I6: 297.15174 | J6: =IF(I6="","",IF(I6=H6,15,MIN(15,-LOG10(ABS(I6-H6)/ABS(H6))))) -> 7.3587544
A7: Bennett5 | B7: Higher Level of Difficulty | C7: 1 | D7: b2 | E7: 46.736565 | F7: 46.736565 | G7: =IF(F7="","",IF(F7=E7,15,MIN(15,-LOG10(ABS(F7-E7)/ABS(E7))))) -> 11.032972 | H7: 1.2448872 | I7: 1.2448871 | J7: =IF(I7="","",IF(I7=H7,15,MIN(15,-LOG10(ABS(I7-H7)/ABS(H7))))) -> 7.3584333
A8: Bennett5 | B8: Higher Level of Difficulty | C8: 1 | D8: b3 | E8: 0.93218483 | F8: 0.93218483 | G8: =IF(F8="","",IF(F8=E8,15,MIN(15,-LOG10(ABS(F8-E8)/ABS(E8))))) -> 11.479547 | H8: 0.020272299 | I8: 0.020272298 | J8: =IF(I8="","",IF(I8=H8,15,MIN(15,-LOG10(ABS(I8-H8)/ABS(H8))))) -> 7.3589054
A9: Bennett5 | B9: Higher Level of Difficulty | C9: 1 | D9: RSS | E9: 0.00052404744 | F9: 0.00052404744 | G9: =IF(F9="","",IF(F9=E9,15,MIN(15,-LOG10(ABS(F9-E9)/ABS(E9))))) -> 11.137755
A10: Bennett5 | B10: Higher Level of Difficulty | C10: 2 | D10: b1 | E10: -2523.5058 | F10: -2523.5058 | G10: =IF(F10="","",IF(F10=E10,15,MIN(15,-LOG10(ABS(F10-E10)/ABS(E10))))) -> 11.763504 | H10: 297.15175 | I10: 297.15177 | J10: =IF(I10="","",IF(I10=H10,15,MIN(15,-LOG10(ABS(I10-H10)/ABS(H10))))) -> 7.4081591
A11: Bennett5 | B11: Higher Level of Difficulty | C11: 2 | D11: b2 | E11: 46.736565 | F11: 46.736565 | G11: =IF(F11="","",IF(F11=E11,15,MIN(15,-LOG10(ABS(F11-E11)/ABS(E11))))) -> 11.041169 | H11: 1.2448872 | I11: 1.2448872 | J11: =IF(I11="","",IF(I11=H11,15,MIN(15,-LOG10(ABS(I11-H11)/ABS(H11))))) -> 7.4086051
A12: Bennett5 | B12: Higher Level of Difficulty | C12: 2 | D12: b3 | E12: 0.93218483 | F12: 0.93218483 | G12: =IF(F12="","",IF(F12=E12,15,MIN(15,-LOG10(ABS(F12-E12)/ABS(E12))))) -> 11.498362 | H12: 0.020272299 | I12: 0.0202723 | J12: =IF(I12="","",IF(I12=H12,15,MIN(15,-LOG10(ABS(I12-H12)/ABS(H12))))) -> 7.4080092
A13: Bennett5 | B13: Higher Level of Difficulty | C13: 2 | D13: RSS | E13: 0.00052404744 | F13: 0.00052404744 | G13: =IF(F13="","",IF(F13=E13,15,MIN(15,-LOG10(ABS(F13-E13)/ABS(E13))))) -> 11.155408
A14: BoxBOD | B14: Higher Level of Difficulty | C14: 1 | D14: b1 | E14: 213.80941 | F14: 213.80941 | G14: =IF(F14="","",IF(F14=E14,15,MIN(15,-LOG10(ABS(F14-E14)/ABS(E14))))) -> 7.9774459 | H14: 12.354515 | I14: 12.354517 | J14: =IF(I14="","",IF(I14=H14,15,MIN(15,-LOG10(ABS(I14-H14)/ABS(H14))))) -> 6.8624627
A15: BoxBOD | B15: Higher Level of Difficulty | C15: 1 | D15: b2 | E15: 0.54723749 | F15: 0.54723746 | G15: =IF(F15="","",IF(F15=E15,15,MIN(15,-LOG10(ABS(F15-E15)/ABS(E15))))) -> 7.3213494 | H15: 0.10455993 | I15: 0.10455991 | J15: =IF(I15="","",IF(I15=H15,15,MIN(15,-LOG10(ABS(I15-H15)/ABS(H15))))) -> 6.6005018
A16: BoxBOD | B16: Higher Level of Difficulty | C16: 1 | D16: RSS | E16: 1168.0089 | F16: 1168.0089 | G16: =IF(F16="","",IF(F16=E16,15,MIN(15,-LOG10(ABS(F16-E16)/ABS(E16))))) -> 10.41977
A17: BoxBOD | B17: Higher Level of Difficulty | C17: 2 | D17: b1 | E17: 213.80941 | F17: 213.80941 | G17: =IF(F17="","",IF(F17=E17,15,MIN(15,-LOG10(ABS(F17-E17)/ABS(E17))))) -> 7.7969254 | H17: 12.354515 | I17: 12.354518 | J17: =IF(I17="","",IF(I17=H17,15,MIN(15,-LOG10(ABS(I17-H17)/ABS(H17))))) -> 6.6819574
A18: BoxBOD | B18: Higher Level of Difficulty | C18: 2 | D18: b2 | E18: 0.54723749 | F18: 0.54723745 | G18: =IF(F18="","",IF(F18=E18,15,MIN(15,-LOG10(ABS(F18-E18)/ABS(E18))))) -> 7.1408072 | H18: 0.10455993 | I18: 0.10455989 | J18: =IF(I18="","",IF(I18=H18,15,MIN(15,-LOG10(ABS(I18-H18)/ABS(H18))))) -> 6.4199549
A19: BoxBOD | B19: Higher Level of Difficulty | C19: 2 | D19: RSS | E19: 1168.0089 | F19: 1168.0089 | G19: =IF(F19="","",IF(F19=E19,15,MIN(15,-LOG10(ABS(F19-E19)/ABS(E19))))) -> 10.419966
A20: Chwirut1 | B20: Lower Level of Difficulty | C20: 1 | D20: b1 | E20: 0.19027818 | F20: 0.19027818 | G20: =IF(F20="","",IF(F20=E20,15,MIN(15,-LOG10(ABS(F20-E20)/ABS(E20))))) -> 8.4644525 | H20: 0.021938557 | I20: 0.021938556 | J20: =IF(I20="","",IF(I20=H20,15,MIN(15,-LOG10(ABS(I20-H20)/ABS(H20))))) -> 7.4484554
A21: Chwirut1 | B21: Lower Level of Difficulty | C21: 1 | D21: b2 | E21: 0.0061314004 | F21: 0.0061314004 | G21: =IF(F21="","",IF(F21=E21,15,MIN(15,-LOG10(ABS(F21-E21)/ABS(E21))))) -> 9.1320122 | H21: 0.00034500025 | I21: 0.00034500025 | J21: =IF(I21="","",IF(I21=H21,15,MIN(15,-LOG10(ABS(I21-H21)/ABS(H21))))) -> 8.0142347
A22: Chwirut1 | B22: Lower Level of Difficulty | C22: 1 | D22: b3 | E22: 0.010530908 | F22: 0.010530908 | G22: =IF(F22="","",IF(F22=E22,15,MIN(15,-LOG10(ABS(F22-E22)/ABS(E22))))) -> 8.7910447 | H22: 0.00079281848 | I22: 0.00079281848 | J22: =IF(I22="","",IF(I22=H22,15,MIN(15,-LOG10(ABS(I22-H22)/ABS(H22))))) -> 8.9761697
A23: Chwirut1 | B23: Lower Level of Difficulty | C23: 1 | D23: RSS | E23: 2384.4771 | F23: 2384.4771 | G23: =IF(F23="","",IF(F23=E23,15,MIN(15,-LOG10(ABS(F23-E23)/ABS(E23))))) -> 11.406579
A24: Chwirut1 | B24: Lower Level of Difficulty | C24: 2 | D24: b1 | E24: 0.19027818 | F24: 0.19027818 | G24: =IF(F24="","",IF(F24=E24,15,MIN(15,-LOG10(ABS(F24-E24)/ABS(E24))))) -> 7.4671812 | H24: 0.021938557 | I24: 0.021938543 | J24: =IF(I24="","",IF(I24=H24,15,MIN(15,-LOG10(ABS(I24-H24)/ABS(H24))))) -> 6.1916659
A25: Chwirut1 | B25: Lower Level of Difficulty | C25: 2 | D25: b2 | E25: 0.0061314004 | F25: 0.0061314005 | G25: =IF(F25="","",IF(F25=E25,15,MIN(15,-LOG10(ABS(F25-E25)/ABS(E25))))) -> 9.0777853 | H25: 0.00034500025 | I25: 0.00034500032 | J25: =IF(I25="","",IF(I25=H25,15,MIN(15,-LOG10(ABS(I25-H25)/ABS(H25))))) -> 6.67382
A26: Chwirut1 | B26: Lower Level of Difficulty | C26: 2 | D26: b3 | E26: 0.010530908 | F26: 0.010530909 | G26: =IF(F26="","",IF(F26=E26,15,MIN(15,-LOG10(ABS(F26-E26)/ABS(E26))))) -> 7.9988097 | H26: 0.00079281848 | I26: 0.00079281849 | J26: =IF(I26="","",IF(I26=H26,15,MIN(15,-LOG10(ABS(I26-H26)/ABS(H26))))) -> 7.8235459
A27: Chwirut1 | B27: Lower Level of Difficulty | C27: 2 | D27: RSS | E27: 2384.4771 | F27: 2384.4771 | G27: =IF(F27="","",IF(F27=E27,15,MIN(15,-LOG10(ABS(F27-E27)/ABS(E27))))) -> 11.406579
A28: Chwirut2 | B28: Lower Level of Difficulty | C28: 1 | D28: b1 | E28: 0.16657667 | F28: 0.16657666 | G28: =IF(F28="","",IF(F28=E28,15,MIN(15,-LOG10(ABS(F28-E28)/ABS(E28))))) -> 7.5235425 | H28: 0.038303287 | I28: 0.038303277 | J28: =IF(I28="","",IF(I28=H28,15,MIN(15,-LOG10(ABS(I28-H28)/ABS(H28))))) -> 6.5966465
A29: Chwirut2 | B29: Lower Level of Difficulty | C29: 1 | D29: b2 | E29: 0.0051653291 | F29: 0.0051653291 | G29: =IF(F29="","",IF(F29=E29,15,MIN(15,-LOG10(ABS(F29-E29)/ABS(E29))))) -> 7.8735974 | H29: 0.00066621605 | I29: 0.00066621611 | J29: =IF(I29="","",IF(I29=H29,15,MIN(15,-LOG10(ABS(I29-H29)/ABS(H29))))) -> 7.0706267
A30: Chwirut2 | B30: Lower Level of Difficulty | C30: 1 | D30: b3 | E30: 0.012150007 | F30: 0.012150007 | G30: =IF(F30="","",IF(F30=E30,15,MIN(15,-LOG10(ABS(F30-E30)/ABS(E30))))) -> 7.82659 | H30: 0.0015304235 | I30: 0.0015304235 | J30: =IF(I30="","",IF(I30=H30,15,MIN(15,-LOG10(ABS(I30-H30)/ABS(H30))))) -> 7.7977266
A31: Chwirut2 | B31: Lower Level of Difficulty | C31: 1 | D31: RSS | E31: 513.04803 | F31: 513.04803 | G31: =IF(F31="","",IF(F31=E31,15,MIN(15,-LOG10(ABS(F31-E31)/ABS(E31))))) -> 11.214058
A32: Chwirut2 | B32: Lower Level of Difficulty | C32: 2 | D32: b1 | E32: 0.16657667 | F32: 0.16657666 | G32: =IF(F32="","",IF(F32=E32,15,MIN(15,-LOG10(ABS(F32-E32)/ABS(E32))))) -> 7.2392263 | H32: 0.038303287 | I32: 0.038303268 | J32: =IF(I32="","",IF(I32=H32,15,MIN(15,-LOG10(ABS(I32-H32)/ABS(H32))))) -> 6.3122406
A33: Chwirut2 | B33: Lower Level of Difficulty | C33: 2 | D33: b2 | E33: 0.0051653291 | F33: 0.005165329 | G33: =IF(F33="","",IF(F33=E33,15,MIN(15,-LOG10(ABS(F33-E33)/ABS(E33))))) -> 7.5892823 | H33: 0.00066621605 | I33: 0.00066621616 | J33: =IF(I33="","",IF(I33=H33,15,MIN(15,-LOG10(ABS(I33-H33)/ABS(H33))))) -> 6.7862894
A34: Chwirut2 | B34: Lower Level of Difficulty | C34: 2 | D34: b3 | E34: 0.012150007 | F34: 0.012150007 | G34: =IF(F34="","",IF(F34=E34,15,MIN(15,-LOG10(ABS(F34-E34)/ABS(E34))))) -> 7.5419961 | H34: 0.0015304235 | I34: 0.0015304235 | J34: =IF(I34="","",IF(I34=H34,15,MIN(15,-LOG10(ABS(I34-H34)/ABS(H34))))) -> 7.513418
A35: Chwirut2 | B35: Lower Level of Difficulty | C35: 2 | D35: RSS | E35: 513.04803 | F35: 513.04803 | G35: =IF(F35="","",IF(F35=E35,15,MIN(15,-LOG10(ABS(F35-E35)/ABS(E35))))) -> 11.214058
A36: DanWood | B36: Lower Level of Difficulty | C36: 1 | D36: b1 | E36: 0.76886226 | F36: 0.76886226 | G36: =IF(F36="","",IF(F36=E36,15,MIN(15,-LOG10(ABS(F36-E36)/ABS(E36))))) -> 10.043589 | H36: 0.018281974 | I36: 0.018281974 | J36: =IF(I36="","",IF(I36=H36,15,MIN(15,-LOG10(ABS(I36-H36)/ABS(H36))))) -> 8.0624388
A37: DanWood | B37: Lower Level of Difficulty | C37: 1 | D37: b2 | E37: 3.8604056 | F37: 3.8604056 | G37: =IF(F37="","",IF(F37=E37,15,MIN(15,-LOG10(ABS(F37-E37)/ABS(E37))))) -> 10.267923 | H37: 0.051726611 | I37: 0.051726611 | J37: =IF(I37="","",IF(I37=H37,15,MIN(15,-LOG10(ABS(I37-H37)/ABS(H37))))) -> 8.7849102
A38: DanWood | B38: Lower Level of Difficulty | C38: 1 | D38: RSS | E38: 0.0043173084 | F38: 0.0043173084 | G38: =IF(F38="","",IF(F38=E38,15,MIN(15,-LOG10(ABS(F38-E38)/ABS(E38))))) -> 11.684344
A39: DanWood | B39: Lower Level of Difficulty | C39: 2 | D39: b1 | E39: 0.76886226 | F39: 0.76886226 | G39: =IF(F39="","",IF(F39=E39,15,MIN(15,-LOG10(ABS(F39-E39)/ABS(E39))))) -> 10.652853 | H39: 0.018281974 | I39: 0.018281974 | J39: =IF(I39="","",IF(I39=H39,15,MIN(15,-LOG10(ABS(I39-H39)/ABS(H39))))) -> 10.687295
A40: DanWood | B40: Lower Level of Difficulty | C40: 2 | D40: b2 | E40: 3.8604056 | F40: 3.8604056 | G40: =IF(F40="","",IF(F40=E40,15,MIN(15,-LOG10(ABS(F40-E40)/ABS(E40))))) -> 10.819109 | H40: 0.051726611 | I40: 0.051726611 | J40: =IF(I40="","",IF(I40=H40,15,MIN(15,-LOG10(ABS(I40-H40)/ABS(H40))))) -> 11.302091
A41: DanWood | B41: Lower Level of Difficulty | C41: 2 | D41: RSS | E41: 0.0043173084 | F41: 0.0043173084 | G41: =IF(F41="","",IF(F41=E41,15,MIN(15,-LOG10(ABS(F41-E41)/ABS(E41))))) -> 11.684344
...

Sheet Bates_Watts
A1: Bates & Watts (1988) — 15 reference models
A2: Reference: exact least-squares minimum computed in R with minpack.lm (nls.lm, tolerances 1e-16, restarted from the solution); standard errors s²(JᵀJ)⁻¹ at the minimum. Not certified values. The reference uses the same MINPACK Levenberg-Marquardt library as the app (tighter tolerances), hence some identical values (LRE = 15); independent check: R nls() (Gauss-Newton) agrees on the RSS to at least 10.4 digits.
A3: App: ENReT v1.0.0, model from “Models for Reference Data” with its starting values, Levenberg-Marquardt, Max Iterations 1024. LRE as in the NIST sheet.
A5: Model | B5: Quantity | C5: Reference | D5: App | E5: LRE | F5: SE reference | G5: SE app | H5: LRE SE
A6: Puromycin, treated cells | B6: theta1 | C6: 212.68374 | D6: 212.68374 | E6: =IF(D6="","",IF(D6=C6,15,MIN(15,-LOG10(ABS(D6-C6)/ABS(C6))))) -> 9.4002202 | F6: 6.9471552 | G6: 6.947155 | H6: =IF(G6="","",IF(G6=F6,15,MIN(15,-LOG10(ABS(G6-F6)/ABS(F6))))) -> 7.6831912
A7: Puromycin, treated cells | B7: theta2 | C7: 0.064121281 | D7: 0.064121281 | E7: =IF(D7="","",IF(D7=C7,15,MIN(15,-LOG10(ABS(D7-C7)/ABS(C7))))) -> 8.5119656 | F7: 0.0082809495 | G7: 0.008280949 | H7: =IF(G7="","",IF(G7=F7,15,MIN(15,-LOG10(ABS(G7-F7)/ABS(F7))))) -> 7.2742876
A8: Puromycin, treated cells | B8: RSS | C8: 1195.4488 | D8: 1195.4488 | E8: =IF(D8="","",IF(D8=C8,15,MIN(15,-LOG10(ABS(D8-C8)/ABS(C8))))) -> 15
A9: Puromycin, untreated cells | B9: theta1 | C9: 160.28005 | D9: 160.28005 | E9: =IF(D9="","",IF(D9=C9,15,MIN(15,-LOG10(ABS(D9-C9)/ABS(C9))))) -> 7.9050935 | F9: 6.4802455 | G9: 6.4802465 | H9: =IF(G9="","",IF(G9=F9,15,MIN(15,-LOG10(ABS(G9-F9)/ABS(F9))))) -> 6.8024113
A10: Puromycin, untreated cells | B10: theta2 | C10: 0.047708185 | D10: 0.047708188 | E10: =IF(D10="","",IF(D10=C10,15,MIN(15,-LOG10(ABS(D10-C10)/ABS(C10))))) -> 7.1872244 | F10: 0.0077818753 | G10: 0.0077818783 | H10: =IF(G10="","",IF(G10=F10,15,MIN(15,-LOG10(ABS(G10-F10)/ABS(F10))))) -> 6.4170904
A11: Puromycin, untreated cells | B11: RSS | C11: 859.60429 | D11: 859.60429 | E11: =IF(D11="","",IF(D11=C11,15,MIN(15,-LOG10(ABS(D11-C11)/ABS(C11))))) -> 13.73246
A12: BOD | B12: theta1 | C12: 19.142575 | D12: 19.142575 | E12: =IF(D12="","",IF(D12=C12,15,MIN(15,-LOG10(ABS(D12-C12)/ABS(C12))))) -> 15 | F12: 2.4959173 | G12: 2.4959173 | H12: =IF(G12="","",IF(G12=F12,15,MIN(15,-LOG10(ABS(G12-F12)/ABS(F12))))) -> 7.7683205
A13: BOD | B13: theta2 | C13: 0.53109138 | D13: 0.53109138 | E13: =IF(D13="","",IF(D13=C13,15,MIN(15,-LOG10(ABS(D13-C13)/ABS(C13))))) -> 15 | F13: 0.2030821 | G13: 0.2030821 | H13: =IF(G13="","",IF(G13=F13,15,MIN(15,-LOG10(ABS(G13-F13)/ABS(F13))))) -> 7.8309956
A14: BOD | B14: RSS | C14: 25.990267 | D14: 25.990267 | E14: =IF(D14="","",IF(D14=C14,15,MIN(15,-LOG10(ABS(D14-C14)/ABS(C14))))) -> 15
A15: BOD2 | B15: theta1 | C15: 2.4979214 | D15: 2.4979214 | E15: =IF(D15="","",IF(D15=C15,15,MIN(15,-LOG10(ABS(D15-C15)/ABS(C15))))) -> 9.0114973 | F15: 0.10756864 | G15: 0.10756865 | H15: =IF(G15="","",IF(G15=F15,15,MIN(15,-LOG10(ABS(G15-F15)/ABS(F15))))) -> 7.6917698
A16: BOD2 | B16: theta2 | C16: 0.20245615 | D16: 0.20245615 | E16: =IF(D16="","",IF(D16=C16,15,MIN(15,-LOG10(ABS(D16-C16)/ABS(C16))))) -> 8.6334613 | F16: 0.017984228 | G16: 0.017984228 | H16: =IF(G16="","",IF(G16=F16,15,MIN(15,-LOG10(ABS(G16-F16)/ABS(F16))))) -> 8.1315894
A17: BOD2 | B17: RSS | C17: 0.026243673 | D17: 0.026243673 | E17: =IF(D17="","",IF(D17=C17,15,MIN(15,-LOG10(ABS(D17-C17)/ABS(C17))))) -> 15
A18: Chloride ion transport | B18: theta1 | C18: 39.094898 | D18: 39.094898 | E18: =IF(D18="","",IF(D18=C18,15,MIN(15,-LOG10(ABS(D18-C18)/ABS(C18))))) -> 15 | F18: 0.97443076 | G18: 0.97443076 | H18: =IF(G18="","",IF(G18=F18,15,MIN(15,-LOG10(ABS(G18-F18)/ABS(F18))))) -> 15
A19: Chloride ion transport | B19: theta2 | C19: 0.82843658 | D19: 0.82843658 | E19: =IF(D19="","",IF(D19=C19,15,MIN(15,-LOG10(ABS(D19-C19)/ABS(C19))))) -> 15 | F19: 0.0083011578 | G19: 0.0083011578 | H19: =IF(G19="","",IF(G19=F19,15,MIN(15,-LOG10(ABS(G19-F19)/ABS(F19))))) -> 15
A20: Chloride ion transport | B20: theta3 | C20: 0.15852239 | D20: 0.15852239 | E20: =IF(D20="","",IF(D20=C20,15,MIN(15,-LOG10(ABS(D20-C20)/ABS(C20))))) -> 15 | F20: 0.010443969 | G20: 0.010443969 | H20: =IF(G20="","",IF(G20=F20,15,MIN(15,-LOG10(ABS(G20-F20)/ABS(F20))))) -> 14.016207
A21: Chloride ion transport | B21: RSS | C21: 1.8793238 | D21: 1.8793238 | E21: =IF(D21="","",IF(D21=C21,15,MIN(15,-LOG10(ABS(D21-C21)/ABS(C21))))) -> 15
A22: Growth of leaves | B22: theta1 | C22: 21.204038 | D22: 21.204038 | E22: =IF(D22="","",IF(D22=C22,15,MIN(15,-LOG10(ABS(D22-C22)/ABS(C22))))) -> 8.4591031 | F22: 0.44359993 | G22: 0.44359984 | H22: =IF(G22="","",IF(G22=F22,15,MIN(15,-LOG10(ABS(G22-F22)/ABS(F22))))) -> 6.7055141
A23: Growth of leaves | B23: theta2 | C23: 296.44956 | D23: 296.4494 | E23: =IF(D23="","",IF(D23=C23,15,MIN(15,-LOG10(ABS(D23-C23)/ABS(C23))))) -> 6.2752013 | F23: 542.66379 | G23: 542.66557 | H23: =IF(G23="","",IF(G23=F23,15,MIN(15,-LOG10(ABS(G23-F23)/ABS(F23))))) -> 5.4841046
A24: Growth of leaves | B24: theta3 | C24: 0.77721843 | D24: 0.77721838 | E24: =IF(D24="","",IF(D24=C24,15,MIN(15,-LOG10(ABS(D24-C24)/ABS(C24))))) -> 7.1808121 | F24: 0.17837567 | G24: 0.17837576 | H24: =IF(G24="","",IF(G24=F24,15,MIN(15,-LOG10(ABS(G24-F24)/ABS(F24))))) -> 6.2958885
A25: Growth of leaves | B25: theta4 | C25: 1.6189088 | D25: 1.6189086 | E25: =IF(D25="","",IF(D25=C25,15,MIN(15,-LOG10(ABS(D25-C25)/ABS(C25))))) -> 6.9386814 | F25: 0.66545185 | G25: 0.66545216 | H25: =IF(G25="","",IF(G25=F25,15,MIN(15,-LOG10(ABS(G25-F25)/ABS(F25))))) -> 6.3360979
A26: Growth of leaves | B26: RSS | C26: 5.5228835 | D26: 5.5228835 | E26: =IF(D26="","",IF(D26=C26,15,MIN(15,-LOG10(ABS(D26-C26)/ABS(C26))))) -> 13.740587
A27: Count Rumford's cooling experiment | B27: theta | C27: 0.0094154963 | D27: 0.0094154963 | E27: =IF(D27="","",IF(D27=C27,15,MIN(15,-LOG10(ABS(D27-C27)/ABS(C27))))) -> 15 | F27: 0.00042008566 | G27: 0.00042008566 | H27: =IF(G27="","",IF(G27=F27,15,MIN(15,-LOG10(ABS(G27-F27)/ABS(F27))))) -> 7.7858526
A28: Count Rumford's cooling experiment | B28: RSS | C28: 44.155795 | D28: 44.155795 | E28: =IF(D28="","",IF(D28=C28,15,MIN(15,-LOG10(ABS(D28-C28)/ABS(C28))))) -> 15
A29: Pharmacokinetics of sulfisoxazole | B29: theta1 | C29: 81.244039 | D29: 81.244039 | E29: =IF(D29="","",IF(D29=C29,15,MIN(15,-LOG10(ABS(D29-C29)/ABS(C29))))) -> 8.6147025 | F29: 6.1073143 | G29: 6.1073148 | H29: =IF(G29="","",IF(G29=F29,15,MIN(15,-LOG10(ABS(G29-F29)/ABS(F29))))) -> 7.1039993
A30: Pharmacokinetics of sulfisoxazole | B30: theta2 | C30: 1.3059889 | D30: 1.3059889 | E30: =IF(D30="","",IF(D30=C30,15,MIN(15,-LOG10(ABS(D30-C30)/ABS(C30))))) -> 7.7778964 | F30: 0.19754134 | G30: 0.19754131 | H30: =IF(G30="","",IF(G30=F30,15,MIN(15,-LOG10(ABS(G30-F30)/ABS(F30))))) -> 6.8195672
A31: Pharmacokinetics of sulfisoxazole | B31: theta3 | C31: 162.59441 | D31: 162.59441 | E31: =IF(D31="","",IF(D31=C31,15,MIN(15,-LOG10(ABS(D31-C31)/ABS(C31))))) -> 8.4366638 | F31: 6.9429875 | G31: 6.9429882 | H31: =IF(G31="","",IF(G31=F31,15,MIN(15,-LOG10(ABS(G31-F31)/ABS(F31))))) -> 7.0004986
A32: Pharmacokinetics of sulfisoxazole | B32: theta4 | C32: 0.16178564 | D32: 0.16178564 | E32: =IF(D32="","",IF(D32=C32,15,MIN(15,-LOG10(ABS(D32-C32)/ABS(C32))))) -> 8.460228 | F32: 0.0087797637 | G32: 0.0087797641 | H32: =IF(G32="","",IF(G32=F32,15,MIN(15,-LOG10(ABS(G32-F32)/ABS(F32))))) -> 7.2909127
A33: Pharmacokinetics of sulfisoxazole | B33: RSS | C33: 34.376471 | D33: 34.376471 | E33: =IF(D33="","",IF(D33=C33,15,MIN(15,-LOG10(ABS(D33-C33)/ABS(C33))))) -> 14.222273
A34: Pharmacokinetics of tetracycline | B34: theta1 | C34: 0.14880089 | D34: 0.14880089 | E34: =IF(D34="","",IF(D34=C34,15,MIN(15,-LOG10(ABS(D34-C34)/ABS(C34))))) -> 8.0862179 | F34: 0.01440942 | G34: 0.014409418 | H34: =IF(G34="","",IF(G34=F34,15,MIN(15,-LOG10(ABS(G34-F34)/ABS(F34))))) -> 6.9160562
A35: Pharmacokinetics of tetracycline | B35: theta2 | C35: 0.71575107 | D35: 0.71575106 | E35: =IF(D35="","",IF(D35=C35,15,MIN(15,-LOG10(ABS(D35-C35)/ABS(C35))))) -> 7.724802 | F35: 0.12605354 | G35: 0.12605355 | H35: =IF(G35="","",IF(G35=F35,15,MIN(15,-LOG10(ABS(G35-F35)/ABS(F35))))) -> 7.1733354
A36: Pharmacokinetics of tetracycline | B36: theta3 | C36: 2.6496465 | D36: 2.6496465 | E36: =IF(D36="","",IF(D36=C36,15,MIN(15,-LOG10(ABS(D36-C36)/ABS(C36))))) -> 7.8644712 | F36: 0.36446539 | G36: 0.36446531 | H36: =IF(G36="","",IF(G36=F36,15,MIN(15,-LOG10(ABS(G36-F36)/ABS(F36))))) -> 6.6204117
A37: Pharmacokinetics of tetracycline | B37: theta4 | C37: 0.41223634 | D37: 0.41223633 | E37: =IF(D37="","",IF(D37=C37,15,MIN(15,-LOG10(ABS(D37-C37)/ABS(C37))))) -> 7.7237566 | F37: 0.094946042 | G37: 0.094946037 | H37: =IF(G37="","",IF(G37=F37,15,MIN(15,-LOG10(ABS(G37-F37)/ABS(F37))))) -> 7.2128496
A38: Pharmacokinetics of tetracycline | B38: RSS | C38: 0.010045314 | D38: 0.010045314 | E38: =IF(D38="","",IF(D38=C38,15,MIN(15,-LOG10(ABS(D38-C38)/ABS(C38))))) -> 14.006858
A39: Pharmacokinetics of saccharin | B39: theta1 | C39: 0.038707885 | D39: 0.038707885 | E39: =IF(D39="","",IF(D39=C39,15,MIN(15,-LOG10(ABS(D39-C39)/ABS(C39))))) -> 8.313352 | F39: 0.001770515 | G39: 0.001770515 | H39: =IF(G39="","",IF(G39=F39,15,MIN(15,-LOG10(ABS(G39-F39)/ABS(F39))))) -> 8.0301663
A40: Pharmacokinetics of saccharin | B40: theta2 | C40: 0.30506474 | D40: 0.30506473 | E40: =IF(D40="","",IF(D40=C40,15,MIN(15,-LOG10(ABS(D40-C40)/ABS(C40))))) -> 8.011985 | F40: 0.035499689 | G40: 0.035499682 | H40: =IF(G40="","",IF(G40=F40,15,MIN(15,-LOG10(ABS(G40-F40)/ABS(F40))))) -> 6.7159997
A41: Pharmacokinetics of saccharin | B41: theta3 | C41: 762.93817 | D41: 762.93817 | E41: =IF(D41="","",IF(D41=C41,15,MIN(15,-LOG10(ABS(D41-C41)/ABS(C41))))) -> 8.2113448 | F41: 45.113232 | G41: 45.113231 | H41: =IF(G41="","",IF(G41=F41,15,MIN(15,-LOG10(ABS(G41-F41)/ABS(F41))))) -> 7.7071527
...

Sheet Esterase
A1: Carroll & Ruppert (1988) — Esterase assay, weighted least squares
A2: Data: Table 2.3 (108 observations, 5 asterisked observations excluded). Model b0 + b1·x. Reference: R lm() without weights, and with weights 1/fitted² iterated to convergence (ζ = 2).
A3: Book: Example 2.2, pp. 48–51 (published values, 2–4 significant digits). The small differences from the book are already present without weighting (see the statistical document, section 4.3).
A5: Weighting | B5: Quantity | C5: Reference (R) | D5: App | E5: LRE | F5: Book | G5: Difference app vs book (%)
A6: None | B6: b0 | C6: -17.4122 | D6: -17.4122 | E6: =IF(D6="","",IF(D6=C6,15,MIN(15,-LOG10(ABS(D6-C6)/ABS(C6))))) -> 15 | F6: -17.02 | G6: =IF(F6="","",(D6-F6)/ABS(F6)) -> -0.023043476
A7: None | B7: b1 | C7: 17.066213 | D7: 17.066213 | E7: =IF(D7="","",IF(D7=C7,15,MIN(15,-LOG10(ABS(D7-C7)/ABS(C7))))) -> 15 | F7: 17.05 | G7: =IF(F7="","",(D7-F7)/ABS(F7)) -> 0.00095090213
A8: None | B8: se_b0 | C8: 20.510594 | D8: 20.510594 | E8: =IF(D8="","",IF(D8=C8,15,MIN(15,-LOG10(ABS(D8-C8)/ABS(C8))))) -> 15 | G8: =IF(F8="","",(D8-F8)/ABS(F8))
A9: None | B9: se_b1 | C9: 0.89278785 | D9: 0.89278785 | E9: =IF(D9="","",IF(D9=C9,15,MIN(15,-LOG10(ABS(D9-C9)/ABS(C9))))) -> 15 | G9: =IF(F9="","",(D9-F9)/ABS(F9))
A10: None | B10: sigma | C10: 101.84672 | D10: 101.84672 | E10: =IF(D10="","",IF(D10=C10,15,MIN(15,-LOG10(ABS(D10-C10)/ABS(C10))))) -> 15 | G10: =IF(F10="","",(D10-F10)/ABS(F10))
A11: 1/ŷ² (ζ = 2) | B11: b0 | C11: -37.981843 | D11: -37.981843 | E11: =IF(D11="","",IF(D11=C11,15,MIN(15,-LOG10(ABS(D11-C11)/ABS(C11))))) -> 9.377352 | F11: -37.36 | G11: =IF(F11="","",(D11-F11)/ABS(F11)) -> -0.016644612
A12: 1/ŷ² (ζ = 2) | B12: b1 | C12: 18.180098 | D12: 18.180098 | E12: =IF(D12="","",IF(D12=C12,15,MIN(15,-LOG10(ABS(D12-C12)/ABS(C12))))) -> 10.233064 | F12: 18.16 | G12: =IF(F12="","",(D12-F12)/ABS(F12)) -> 0.001106702
A13: 1/ŷ² (ζ = 2) | B13: se_b0 | C13: 12.234021 | D13: 12.234021 | E13: =IF(D13="","",IF(D13=C13,15,MIN(15,-LOG10(ABS(D13-C13)/ABS(C13))))) -> 10.393579 | F13: 12.21 | G13: =IF(F13="","",(D13-F13)/ABS(F13)) -> 0.0019673213
A14: 1/ŷ² (ζ = 2) | B14: se_b1 | C14: 0.94713818 | D14: 0.94713818 | E14: =IF(D14="","",IF(D14=C14,15,MIN(15,-LOG10(ABS(D14-C14)/ABS(C14))))) -> 11.349361 | F14: 0.95 | G14: =IF(F14="","",(D14-F14)/ABS(F14)) -> -0.003012446
A15: 1/ŷ² (ζ = 2) | B15: sigma | C15: 0.27720159 | D15: 0.27720159 | E15: =IF(D15="","",IF(D15=C15,15,MIN(15,-LOG10(ABS(D15-C15)/ABS(C15))))) -> 11.48807 | F15: 0.27 | G15: =IF(F15="","",(D15-F15)/ABS(F15)) -> 0.026672558

Sheet ComBase
A1: ComBase — 26 Salmonella growth curves, Baranyi & Roberts model
A2: ComBase: parameters from the ComBase fit (Baranyi & Roberts, 1994, n = m = 1, fitted on ln counts, reported in log10). App: custom formula, the same model written for log10 counts (24 complete curves; 2 without asymptote: y = N0 + μ·A(t)).
A3: Differences in % and in ComBase standard errors (z = (App − ComBase) / SE ComBase). ComBase values are rounded to 3–4 digits, so LRE is not used. SE of Fit (ComBase) and RMSE (app) are the same quantity, √[SSE/(n − p)].
A5: Series | B5: Model | C5: Parameter | D5: ComBase | E5: SE ComBase | F5: App | G5: SE app | H5: Difference (%) | I5: Difference in SE (z) | J5: |z| | K5: Difference of SE (%)
A6: B092_25 | B6: complete | C6: N0 | D6: 2.597 | E6: 0.144 | F6: 2.6080974 | G6: 0.13665184 | H6: =(F6-D6)/ABS(D6) -> 0.0042731432 | I6: =(F6-D6)/E6 -> 0.077064951 | J6: =ABS(I6) -> 0.077064951 | K6: =(G6-E6)/E6 -> -0.051028899
A7: B092_25 | B7: complete | C7: lag | D7: 48.0058 | E7: 15.139 | F7: 42.780735 | G7: 12.96667 | H7: =(F7-D7)/ABS(D7) -> -0.10884237 | I7: =(F7-D7)/E7 -> -0.34513937 | J7: =ABS(I7) -> 0.34513937 | K7: =(G7-E7)/E7 -> -0.14349232
A8: B092_25 | B8: complete | C8: mu_max | D8: 0.0153 | E8: 0.000586 | F8: 0.014821563 | G8: 0.00043094825 | H8: =(F8-D8)/ABS(D8) -> -0.031270416 | I8: =(F8-D8)/E8 -> -0.81644602 | J8: =ABS(I8) -> 0.81644602 | K8: =(G8-E8)/E8 -> -0.26459343
A9: B092_25 | B9: complete | C9: log_Nmax | D9: 8.658 | E9: 0.104 | F9: 8.5954697 | G9: 0.082969466 | H9: =(F9-D9)/ABS(D9) -> -0.0072222603 | I9: =(F9-D9)/E9 -> -0.60125317 | J9: =ABS(I9) -> 0.60125317 | K9: =(G9-E9)/E9 -> -0.20221667
A10: B092_25 | B10: complete | C10: SE of Fit / RMSE | D10: 0.166 | F10: 0.15004179 | H10: =(F10-D10)/ABS(D10) -> -0.096133791
A11: B092_25 | B11: complete | C11: R-square (adjusted) | D11: 0.994 | F11: 0.99528789 | H11: =(F11-D11)/ABS(D11) -> 0.0012956665
A12: B092_45 | B12: complete | C12: N0 | D12: 3.515 | E12: 0.509 | F12: 3.4651597 | G12: 0.50090679 | H12: =(F12-D12)/ABS(D12) -> -0.014179306 | I12: =(F12-D12)/E12 -> -0.097917994 | J12: =ABS(I12) -> 0.097917994 | K12: =(G12-E12)/E12 -> -0.015900215
A13: B092_45 | B13: complete | C13: lag | D13: 119.611 | E13: 56.452 | F13: 107.01048 | G13: 53.245278 | H13: =(F13-D13)/ABS(D13) -> -0.10534585 | I13: =(F13-D13)/E13 -> -0.22320773 | J13: =ABS(I13) -> 0.22320773 | K13: =(G13-E13)/E13 -> -0.056804408
A14: B092_45 | B14: complete | C14: mu_max | D14: 0.0157 | E14: 0.00314 | F14: 0.015103739 | G14: 0.0026808551 | H14: =(F14-D14)/ABS(D14) -> -0.037978383 | I14: =(F14-D14)/E14 -> -0.18989192 | J14: =ABS(I14) -> 0.18989192 | K14: =(G14-E14)/E14 -> -0.14622451
A15: B092_45 | B15: complete | C15: log_Nmax | D15: 8.645 | E15: 0.298 | F15: 8.6468399 | G15: 0.28722813 | H15: =(F15-D15)/ABS(D15) -> 0.00021282872 | I15: =(F15-D15)/E15 -> 0.0061741755 | J15: =ABS(I15) -> 0.0061741755 | K15: =(G15-E15)/E15 -> -0.036147222
A16: B092_45 | B16: complete | C16: SE of Fit / RMSE | D16: 0.631 | F16: 0.62746292 | H16: =(F16-D16)/ABS(D16) -> -0.0056055093
A17: B092_45 | B17: complete | C17: R-square (adjusted) | D17: 0.872 | F17: 0.87383764 | H17: =(F17-D17)/ABS(D17) -> 0.0021073815
A18: B092_4 | B18: complete | C18: N0 | D18: 3.194 | E18: 0.119 | F18: 3.2114304 | G18: 0.11819789 | H18: =(F18-D18)/ABS(D18) -> 0.0054572467 | I18: =(F18-D18)/E18 -> 0.14647434 | J18: =ABS(I18) -> 0.14647434 | K18: =(G18-E18)/E18 -> -0.0067404499
A19: B092_4 | B19: complete | C19: lag | D19: 68.295 | E19: 14.223 | F19: 66.507215 | G19: 13.752604 | H19: =(F19-D19)/ABS(D19) -> -0.026177389 | I19: =(F19-D19)/E19 -> -0.12569674 | J19: =ABS(I19) -> 0.12569674 | K19: =(G19-E19)/E19 -> -0.033072934
A20: B092_4 | B20: complete | C20: mu_max | D20: 0.0173 | E20: 0.00142 | F20: 0.016948463 | G20: 0.0013203492 | H20: =(F20-D20)/ABS(D20) -> -0.020320063 | I20: =(F20-D20)/E20 -> -0.24756133 | J20: =ABS(I20) -> 0.24756133 | K20: =(G20-E20)/E20 -> -0.070176624
A21: B092_4 | B21: complete | C21: log_Nmax | D21: 7.695 | E21: 0.0979 | F21: 7.6947906 | G21: 0.097113415 | H21: =(F21-D21)/ABS(D21) -> -2.7215667e-05 | I21: =(F21-D21)/E21 -> -0.0021391681 | J21: =ABS(I21) -> 0.0021391681 | K21: =(G21-E21)/E21 -> -0.0080345758
A22: B092_4 | B22: complete | C22: SE of Fit / RMSE | D22: 0.212 | F22: 0.21157578 | H22: =(F22-D22)/ABS(D22) -> -0.0020010603
A23: B092_4 | B23: complete | C23: R-square (adjusted) | D23: 0.984 | F23: 0.98393711 | H23: =(F23-D23)/ABS(D23) -> -6.3912488e-05
A24: B092_32 | B24: complete | C24: N0 | D24: 2.687 | E24: 0.262 | F24: 2.6887413 | G24: 0.27844037 | H24: =(F24-D24)/ABS(D24) -> 0.00064802929 | I24: =(F24-D24)/E24 -> 0.0066460103 | J24: =ABS(I24) -> 0.0066460103 | K24: =(G24-E24)/E24 -> 0.062749486
A25: B092_32 | B25: complete | C25: lag | D25: 38.413 | E25: 28.303 | F25: 32.395332 | G25: 27.584172 | H25: =(F25-D25)/ABS(D25) -> -0.15665707 | I25: =(F25-D25)/E25 -> -0.2126159 | J25: =ABS(I25) -> 0.2126159 | K25: =(G25-E25)/E25 -> -0.025397596
A26: B092_32 | B26: complete | C26: mu_max | D26: 0.0158 | E26: 0.00139 | F26: 0.015240954 | G26: 0.0011636498 | H26: =(F26-D26)/ABS(D26) -> -0.035382669 | I26: =(F26-D26)/E26 -> -0.40219149 | J26: =ABS(I26) -> 0.40219149 | K26: =(G26-E26)/E26 -> -0.16284188
A27: B092_32 | B27: complete | C27: log_Nmax | D27: 8.283 | E27: 0.177 | F27: 8.2498546 | G27: 0.1649319 | H27: =(F27-D27)/ABS(D27) -> -0.0040016223 | I27: =(F27-D27)/E27 -> -0.18726236 | J27: =ABS(I27) -> 0.18726236 | K27: =(G27-E27)/E27 -> -0.068181331
A28: B092_32 | B28: complete | C28: SE of Fit / RMSE | D28: 0.342 | F28: 0.34253698 | H28: =(F28-D28)/ABS(D28) -> 0.0015701105
A29: B092_32 | B29: complete | C29: R-square (adjusted) | D29: 0.97 | F29: 0.97030366 | H29: =(F29-D29)/ABS(D29) -> 0.00031304751
A30: B092_17 | B30: complete | C30: N0 | D30: 3.906 | E30: 0.108 | F30: 3.9385526 | G30: 0.10278333 | H30: =(F30-D30)/ABS(D30) -> 0.0083339904 | I30: =(F30-D30)/E30 -> 0.30141265 | J30: =ABS(I30) -> 0.30141265 | K30: =(G30-E30)/E30 -> -0.04830252
A31: B092_17 | B31: complete | C31: lag | D31: 79.273 | E31: 9.57 | F31: 76.454988 | G31: 8.8671731 | H31: =(F31-D31)/ABS(D31) -> -0.035548199 | I31: =(F31-D31)/E31 -> -0.29446315 | J31: =ABS(I31) -> 0.29446315 | K31: =(G31-E31)/E31 -> -0.073440641
A32: B092_17 | B32: complete | C32: mu_max | D32: 0.0313 | E32: 0.00277 | F32: 0.030092281 | G32: 0.0025215298 | H32: =(F32-D32)/ABS(D32) -> -0.038585277 | I32: =(F32-D32)/E32 -> -0.43599969 | J32: =ABS(I32) -> 0.43599969 | K32: =(G32-E32)/E32 -> -0.089700442
A33: B092_17 | B33: complete | C33: log_Nmax | D33: 9.0401 | E33: 0.253 | F33: 9.0373072 | G33: 0.25028161 | H33: =(F33-D33)/ABS(D33) -> -0.00030893931 | I33: =(F33-D33)/E33 -> -0.011038902 | J33: =ABS(I33) -> 0.011038902 | K33: =(G33-E33)/E33 -> -0.010744619
A34: B092_17 | B34: complete | C34: SE of Fit / RMSE | D34: 0.323 | F34: 0.32814661 | H34: =(F34-D34)/ABS(D34) -> 0.015933764
A35: B092_17 | B35: complete | C35: R-square (adjusted) | D35: 0.969 | F35: 0.96815473 | H35: =(F35-D35)/ABS(D35) -> -0.0008723077
A36: B146_1 | B36: complete | C36: N0 | D36: 3.967 | E36: 0.0985 | F36: 3.9669666 | G36: 0.098078441 | H36: =(F36-D36)/ABS(D36) -> -8.4292664e-06 | I36: =(F36-D36)/E36 -> -0.00033948122 | J36: =ABS(I36) -> 0.00033948122 | K36: =(G36-E36)/E36 -> -0.0042797833
A37: B146_1 | B37: complete | C37: lag | D37: 90.373 | E37: 33.0445 | F37: 86.841323 | G37: 29.472383 | H37: =(F37-D37)/ABS(D37) -> -0.039078894 | I37: =(F37-D37)/E37 -> -0.10687639 | J37: =ABS(I37) -> 0.10687639 | K37: =(G37-E37)/E37 -> -0.1081002
A38: B146_1 | B38: complete | C38: mu_max | D38: 0.0808 | E38: 0.0499 | F38: 0.075576399 | G38: 0.038330697 | H38: =(F38-D38)/ABS(D38) -> -0.064648533 | I38: =(F38-D38)/E38 -> -0.10468139 | J38: =ABS(I38) -> 0.10468139 | K38: =(G38-E38)/E38 -> -0.23184977
A39: B146_1 | B39: complete | C39: log_Nmax | D39: 8.403 | E39: 0.0843 | F39: 8.4025705 | G39: 0.084327999 | H39: =(F39-D39)/ABS(D39) -> -5.1118517e-05 | I39: =(F39-D39)/E39 -> -0.0050954792 | J39: =ABS(I39) -> 0.0050954792 | K39: =(G39-E39)/E39 -> 0.00033213567
A40: B146_1 | B40: complete | C40: SE of Fit / RMSE | D40: 0.169 | F40: 0.16862621 | H40: =(F40-D40)/ABS(D40) -> -0.0022117796
A41: B146_1 | B41: complete | C41: R-square (adjusted) | D41: 0.995 | F41: 0.99463429 | H41: =(F41-D41)/ABS(D41) -> -0.0003675493
...

Sheet ComBase_B419_12
A1: ComBase — detailed checks on series B419_12 (same 10 data points)
A2: Linear model: closed-form solution, no iterative algorithm, so it checks data, standard errors and SE of Fit. Baranyi & Roberts: ComBase parameters vs the least-squares minimum found by the app with the same model.
A3: ComBase “R-square” corresponds to the adjusted R². Blue: input values; black: formulas.
A5: 1. Linear model
A6: Quantity | B6: ComBase | C6: App | D6: Difference (%)
A7: Initial value | B7: 2.552 | C7: 2.5517395 | D7: =(C7-B7)/ABS(B7) -> -0.00010205878
A8: SE initial value | B8: 0.452 | C8: 0.45237257 | D8: =(C8-B8)/ABS(B8) -> 0.00082427412
A9: Max. Rate | B9: 0.0333 | C9: 0.033297662 | D9: =(C9-B9)/ABS(B9) -> -7.0216517e-05
A10: SE max. rate | B10: 0.00349 | C10: 0.0034850976 | D10: =(C10-B10)/ABS(B10) -> -0.0014046997
A11: SE of Fit / RMSE | B11: 0.768 | C11: 0.76808335 | D11: =(C11-B11)/ABS(B11) -> 0.00010852747
A12: R-square (adjusted) | B12: 0.909 | C12: 0.90935151 | D12: =(C12-B12)/ABS(B12) -> 0.00038670396
A14: 2. Baranyi & Roberts, complete model
A15: Quantity | B15: ComBase | C15: App (least-squares minimum) | D15: Difference (%)
A16: Initial value | B16: 2.294 | C16: 2.3031242 | D16: =(C16-B16)/ABS(B16) -> 0.0039774359
A17: SE initial value | B17: 0.0987 | C17: 0.074331524 | D17: =(C17-B17)/ABS(B17) -> -0.24689439
A18: Lag/shoulder (h) | B18: 23.119 | C18: 19.958869 | D18: =(C18-B18)/ABS(B18) -> -0.1366898
A19: SE lag | B19: 3.52 | C19: 2.4623854 | D19: =(C19-B19)/ABS(B19) -> -0.3004587
A20: Max. Rate | B20: 0.0539 | C20: 0.051128064 | D20: =(C20-B20)/ABS(B20) -> -0.051427386
A21: SE max. rate | B21: 0.00198 | C21: 0.0011900053 | D21: =(C21-B21)/ABS(B21) -> -0.39898722
A22: MPD | B22: 8.659 | C22: 8.6387682 | D22: =(C22-B22)/ABS(B22) -> -0.0023365021
A23: SE MPD | B23: 0.0649 | C23: 0.045175914 | D23: =(C23-B23)/ABS(B23) -> -0.30391504
A24: SE of Fit / RMSE | B24: 0.108 | C24: 0.07832025 | D24: =(C24-B24)/ABS(B24) -> -0.2748125
A25: R-square (adjusted) | B25: 0.998 | C25: 0.99905748 | D25: =(C25-B25)/ABS(B25) -> 0.0010595961
A27: 3. Criteria evaluated at the two parameter sets (lower is better)
A28: Criterion | B28: ComBase parameters | C28: App parameters | D28: Ratio app / ComBase
A29: Sum of squares (log10) | B29: 0.076543433 | C29: 0.036804369 | D29: =C29/B29 -> 0.48082987
A30: Sum of squares (ln) | B30: 0.40582548 | C30: 0.19513301 | D30: =C30/B30 -> 0.48082987
A31: Sum of absolute residuals | B31: 0.65129869 | C31: 0.52478524 | D31: =C31/B31 -> 0.80575203
A32: Maximum absolute residual | B32: 0.20403714 | C32: 0.1095107 | D32: =C32/B32 -> 0.53671946
A34: The app's least-squares minimum is better on every criterion: the ComBase fit stops before the minimum of the same model on the same data.
